<?xml version="1.0" encoding="utf-8"?>
<!--
  Unitree Go1 Quadruped — adapted for torque-control RL training.
  Original model from Google DeepMind mujoco_menagerie (BSD-3-Clause).
  See assets/go1/LICENSE_GO1 for the original license.

  Modifications from menagerie go1.xml:
    - Position actuators → motor actuators (env implements PD in Python)
    - Added floor, lighting, textures for standalone scene
    - Added IMU site + sensors
    - Motor ctrlrange set to ±33.5 Nm (max of Go1 actuator force ranges)
-->
<mujoco model="go1">
  <compiler angle="radian" meshdir="go1" autolimits="true"/>
  <option timestep="0.002" gravity="0 0 -9.81" iterations="50" solver="Newton"
          cone="elliptic" impratio="100"/>

  <visual>
    <headlight ambient="0.5 0.5 0.5" diffuse="0.8 0.8 0.8" specular="0.1 0.1 0.1"/>
    <map force="0.1" zfar="30"/>
    <quality shadowsize="2048"/>
  </visual>

  <asset>
    <texture type="skybox" builtin="gradient" rgb1="0.4 0.6 0.8" rgb2="0.05 0.05 0.2"
             width="100" height="100"/>
    <texture name="floor_tex" type="2d" builtin="checker" rgb1="0.6 0.6 0.6"
             rgb2="0.4 0.4 0.4" width="300" height="300"/>
    <material name="floor_mat" texture="floor_tex" texrepeat="10 10"
              specular="0.5" shininess="0.3" reflectance="0.1"/>
    <material name="dark" rgba="0.2 0.2 0.2 1"/>

    <mesh file="trunk.stl"/>
    <mesh file="hip.stl"/>
    <mesh file="thigh_mirror.stl"/>
    <mesh file="calf.stl"/>
    <mesh file="thigh.stl"/>
  </asset>

  <default>
    <default class="go1">
      <geom friction="0.6" margin="0.001" condim="1"/>
      <joint axis="0 1 0" damping="2" armature="0.01" frictionloss="0.2"/>
      <default class="abduction">
        <joint axis="1 0 0" damping="1" range="-0.863 0.863"/>
      </default>
      <default class="hip">
        <joint range="-0.686 4.501"/>
      </default>
      <default class="knee">
        <joint range="-2.818 -0.888"/>
      </default>
      <default class="visual">
        <geom type="mesh" contype="0" conaffinity="0" group="2" material="dark"/>
      </default>
      <default class="collision">
        <geom group="3" type="capsule"/>
        <default class="hip_left1">
          <geom size="0.046 0.02" pos="0 0.045 0" quat="1 1 0 0" type="cylinder"/>
        </default>
        <default class="hip_left2">
          <geom size="0.031 0.02" pos="0 0.065 0" quat="1 1 0 0" type="cylinder"/>
        </default>
        <default class="hip_left3">
          <geom size="0.046 0.02" quat="1 1 0 0" type="cylinder"/>
        </default>
        <default class="hip_right1">
          <geom size="0.046 0.02" pos="0 -0.045 0" quat="1 1 0 0" type="cylinder"/>
        </default>
        <default class="hip_right2">
          <geom size="0.031 0.02" pos="0 -0.065 0" quat="1 1 0 0" type="cylinder"/>
        </default>
        <default class="hip_right3">
          <geom size="0.046 0.02" quat="1 1 0 0" type="cylinder"/>
        </default>
        <default class="thigh1">
          <geom size="0.015" fromto="-0.02 0 0 -0.02 0 -0.16"/>
        </default>
        <default class="thigh2">
          <geom size="0.015" fromto="0 0 0 -0.02 0 -0.1"/>
        </default>
        <default class="thigh3">
          <geom size="0.015" fromto="-0.02 0 -0.16 0 0 -0.2"/>
        </default>
        <default class="calf1">
          <geom size="0.01" fromto="0 0 0 0.02 0 -0.13"/>
        </default>
        <default class="calf2">
          <geom size="0.01" fromto="0.02 0 -0.13 0 0 -0.2"/>
        </default>
        <default class="foot">
          <geom type="sphere" size="0.023" pos="0 0 -0.213" priority="1"
                solimp="0.015 1 0.023" condim="6" friction="0.8 0.02 0.01"/>
        </default>
      </default>
    </default>
    <motor ctrllimited="true" ctrlrange="-33.5 33.5"/>
  </default>

  <worldbody>
    <light name="top" pos="0 0 3" dir="0 0 -1" directional="true"
           diffuse="0.8 0.8 0.8" specular="0.2 0.2 0.2"/>
    <light name="front" pos="2 -2 2" dir="-1 1 -1" diffuse="0.3 0.3 0.3"/>
    <light name="spotlight" mode="targetbodycom" target="trunk" pos="0 -1 2"/>
    <geom name="floor" type="plane" size="50 50 0.1" material="floor_mat"
          condim="6" friction="1.0 0.005 0.0001"/>

    <body name="trunk" pos="0 0 0.27" childclass="go1">
      <camera name="tracking" mode="trackcom" pos="0 -1 0.8" xyaxes="1 0 0 0 1 1"/>
      <site name="imu_site" pos="0 0 0" size="0.01"/>
      <site name="head" pos="0.3 0 0" rgba="1 0 0 1" size="0.02" group="5"/>
      <inertial pos="0.0223 0.002 -0.0005" quat="-0.00342088 0.705204 0.000106698 0.708996"
                mass="5.204" diaginertia="0.0716565 0.0630105 0.0168101"/>
      <freejoint name="root"/>
      <geom class="visual" mesh="trunk"/>
      <geom class="collision" size="0.125 0.04 0.057" type="box"/>
      <geom class="collision" quat="1 0 1 0" pos="0 -0.04 0" size="0.058 0.125" type="cylinder"/>
      <geom class="collision" quat="1 0 1 0" pos="0 +0.04 0" size="0.058 0.125" type="cylinder"/>
      <geom class="collision" pos="0.25 0 0" size="0.005 0.06 0.05" type="box"/>
      <geom class="collision" pos="0.25 0.06 -0.01" size="0.009 0.035"/>
      <geom class="collision" pos="0.25 -0.06 -0.01" size="0.009 0.035"/>
      <geom class="collision" pos="0.25 0 -0.05" size="0.01 0.06" quat="1 1 0 0"/>
      <geom class="collision" pos="0.255 0 0.0355" size="0.021 0.052" quat="1 1 0 0"/>

      <!-- ═══ FR (Front-Right) leg ═══ -->
      <body name="FR_hip" pos="0.1881 -0.04675 0">
        <inertial pos="-0.0049166 0.00762615 -8.865e-05"
                  quat="0.507341 0.514169 0.495027 0.482891" mass="0.68"
                  diaginertia="0.000734064 0.000468438 0.000398719"/>
        <joint class="abduction" name="FR_hip_joint"/>
        <geom class="visual" mesh="hip" quat="1 0 0 0"/>
        <geom class="hip_right1"/>
        <geom class="hip_right2"/>
        <body name="FR_thigh" pos="0 -0.08 0">
          <inertial pos="-0.00304722 0.019315 -0.0305004"
                    quat="0.65243 -0.0272313 0.0775126 0.753383" mass="1.009"
                    diaginertia="0.00478717 0.00460903 0.000709268"/>
          <joint class="hip" name="FR_thigh_joint"/>
          <geom class="visual" mesh="thigh_mirror"/>
          <geom class="thigh1"/>
          <geom class="thigh2"/>
          <geom class="thigh3"/>
          <body name="FR_calf" pos="0 0 -0.213">
            <inertial pos="0.00429862 0.000976676 -0.146197"
                      quat="0.691246 0.00357467 0.00511118 0.722592"
                      mass="0.195862" diaginertia="0.00149767 0.00148468 3.58427e-05"/>
            <joint class="knee" name="FR_calf_joint"/>
            <geom class="visual" mesh="calf"/>
            <geom class="calf1"/>
            <geom class="calf2"/>
            <geom name="FR" class="foot"/>
            <site name="FR_foot_site" pos="0 0 -0.213" type="sphere" size="0.023" group="5"/>
          </body>
        </body>
      </body>

      <!-- ═══ FL (Front-Left) leg ═══ -->
      <body name="FL_hip" pos="0.1881 0.04675 0">
        <inertial pos="-0.0049166 -0.00762615 -8.865e-05"
                  quat="0.482891 0.495027 0.514169 0.507341" mass="0.68"
                  diaginertia="0.000734064 0.000468438 0.000398719"/>
        <joint class="abduction" name="FL_hip_joint"/>
        <geom class="visual" mesh="hip"/>
        <geom class="hip_left1"/>
        <geom class="hip_left2"/>
        <body name="FL_thigh" pos="0 0.08 0">
          <inertial pos="-0.00304722 -0.019315 -0.0305004"
                    quat="0.753383 0.0775126 -0.0272313 0.65243" mass="1.009"
                    diaginertia="0.00478717 0.00460903 0.000709268"/>
          <joint class="hip" name="FL_thigh_joint"/>
          <geom class="visual" mesh="thigh"/>
          <geom class="thigh1"/>
          <geom class="thigh2"/>
          <geom class="thigh3"/>
          <body name="FL_calf" pos="0 0 -0.213">
            <inertial pos="0.00429862 0.000976676 -0.146197"
                      quat="0.691246 0.00357467 0.00511118 0.722592"
                      mass="0.195862" diaginertia="0.00149767 0.00148468 3.58427e-05"/>
            <joint class="knee" name="FL_calf_joint"/>
            <geom class="visual" mesh="calf"/>
            <geom class="calf1"/>
            <geom class="calf2"/>
            <geom name="FL" class="foot"/>
            <site name="FL_foot_site" pos="0 0 -0.213" type="sphere" size="0.023" group="5"/>
          </body>
        </body>
      </body>

      <!-- ═══ RR (Rear-Right) leg ═══ -->
      <body name="RR_hip" pos="-0.1881 -0.04675 0">
        <inertial pos="0.0049166 0.00762615 -8.865e-05"
                  quat="0.495027 0.482891 0.507341 0.514169" mass="0.68"
                  diaginertia="0.000734064 0.000468438 0.000398719"/>
        <joint class="abduction" name="RR_hip_joint"/>
        <geom class="visual" quat="0 0 0 -1" mesh="hip"/>
        <geom class="hip_right1"/>
        <geom class="hip_right2"/>
        <geom class="hip_right3"/>
        <body name="RR_thigh" pos="0 -0.08 0">
          <inertial pos="-0.00304722 0.019315 -0.0305004"
                    quat="0.65243 -0.0272313 0.0775126 0.753383" mass="1.009"
                    diaginertia="0.00478717 0.00460903 0.000709268"/>
          <joint class="hip" name="RR_thigh_joint"/>
          <geom class="visual" mesh="thigh_mirror"/>
          <geom class="thigh1"/>
          <geom class="thigh2"/>
          <geom class="thigh3"/>
          <body name="RR_calf" pos="0 0 -0.213">
            <inertial pos="0.00429862 0.000976676 -0.146197"
                      quat="0.691246 0.00357467 0.00511118 0.722592"
                      mass="0.195862" diaginertia="0.00149767 0.00148468 3.58427e-05"/>
            <joint class="knee" name="RR_calf_joint"/>
            <geom class="visual" mesh="calf"/>
            <geom class="calf1"/>
            <geom class="calf2"/>
            <geom name="RR" class="foot"/>
            <site name="RR_foot_site" pos="0 0 -0.213" type="sphere" size="0.023" group="5"/>
          </body>
        </body>
      </body>

      <!-- ═══ RL (Rear-Left) leg ═══ -->
      <body name="RL_hip" pos="-0.1881 0.04675 0">
        <inertial pos="0.0049166 -0.00762615 -8.865e-05"
                  quat="0.514169 0.507341 0.482891 0.495027" mass="0.68"
                  diaginertia="0.000734064 0.000468438 0.000398719"/>
        <joint class="abduction" name="RL_hip_joint"/>
        <geom class="visual" quat="0 0 1 0" mesh="hip"/>
        <geom class="hip_left1"/>
        <geom class="hip_left2"/>
        <geom class="hip_left3"/>
        <body name="RL_thigh" pos="0 0.08 0">
          <inertial pos="-0.00304722 -0.019315 -0.0305004"
                    quat="0.753383 0.0775126 -0.0272313 0.65243" mass="1.009"
                    diaginertia="0.00478717 0.00460903 0.000709268"/>
          <joint class="hip" name="RL_thigh_joint"/>
          <geom class="visual" mesh="thigh"/>
          <geom class="thigh1"/>
          <geom class="thigh2"/>
          <geom class="thigh3"/>
          <body name="RL_calf" pos="0 0 -0.213">
            <inertial pos="0.00429862 0.000976676 -0.146197"
                      quat="0.691246 0.00357467 0.00511118 0.722592"
                      mass="0.195862" diaginertia="0.00149767 0.00148468 3.58427e-05"/>
            <joint class="knee" name="RL_calf_joint"/>
            <geom class="visual" mesh="calf"/>
            <geom class="calf1"/>
            <geom class="calf2"/>
            <geom name="RL" class="foot"/>
            <site name="RL_foot_site" pos="0 0 -0.213" type="sphere" size="0.023" group="5"/>
          </body>
        </body>
      </body>
    </body>
  </worldbody>

  <!-- Motor actuators: env implements PD control in Python -->
  <actuator>
    <motor name="FR_hip_motor"   joint="FR_hip_joint"   gear="1"/>
    <motor name="FR_thigh_motor" joint="FR_thigh_joint" gear="1"/>
    <motor name="FR_calf_motor"  joint="FR_calf_joint"  gear="1"/>
    <motor name="FL_hip_motor"   joint="FL_hip_joint"   gear="1"/>
    <motor name="FL_thigh_motor" joint="FL_thigh_joint" gear="1"/>
    <motor name="FL_calf_motor"  joint="FL_calf_joint"  gear="1"/>
    <motor name="RR_hip_motor"   joint="RR_hip_joint"   gear="1"/>
    <motor name="RR_thigh_motor" joint="RR_thigh_joint" gear="1"/>
    <motor name="RR_calf_motor"  joint="RR_calf_joint"  gear="1"/>
    <motor name="RL_hip_motor"   joint="RL_hip_joint"   gear="1"/>
    <motor name="RL_thigh_motor" joint="RL_thigh_joint" gear="1"/>
    <motor name="RL_calf_motor"  joint="RL_calf_joint"  gear="1"/>
  </actuator>

  <sensor>
    <framelinvel name="base_linvel" objtype="site" objname="imu_site"/>
    <frameangvel name="base_angvel" objtype="site" objname="imu_site"/>
    <framequat name="base_quat" objtype="site" objname="imu_site"/>
    <accelerometer name="base_accel" site="imu_site"/>
    <gyro name="base_gyro" site="imu_site"/>
  </sensor>

  <keyframe>
    <key name="home" qpos="0 0 0.27 1 0 0 0 0 0.9 -1.8 0 0.9 -1.8 0 0.9 -1.8 0 0.9 -1.8"
         ctrl="0 0 0 0 0 0 0 0 0 0 0 0"/>
  </keyframe>
</mujoco>
