<mujoco model="mini_cheetah">
  <compiler angle="radian"/>

  <worldbody>
    <geom size="0.15 0.1 0.0465" type="box" rgba="0.823529 0.823529 0.823529 1"/>
    <body name="RL_hip" pos="-0.196 0.049664 0">
      <inertial pos="0 -0.036 0" quat="0.707107 0 0 0.707107" mass="0.57" diaginertia="0.000795577 0.000714827 0.00068875"/>
      <joint name="RL_hip_joint" pos="0 0 0" axis="1 0 0" range="-0.872665 1.0472" actuatorfrcrange="-20 20"/>
      <geom size="0.045 0.04 0.0465" type="box" rgba="0.811765 0.678431 0.301961 1"/>
      <body name="RL_thigh" pos="0 0.077476 0">
        <inertial pos="0 -0.016 -0.11" quat="0.707107 0 0 0.707107" mass="0.634" diaginertia="0.00265482 0.00261821 0.000158764"/>
        <joint name="RL_thigh_joint" pos="0 0 0" axis="0 1 0" range="-0.523599 3.92699" actuatorfrcrange="-20 20"/>
        <geom size="0.0215 0.017 0.11" pos="0 0 -0.11" type="box" rgba="0.462745 0.8 0.992157 1"/>
        <body name="RL_calf" pos="0 0 -0.2115">
          <inertial pos="0 0 -0.161488" mass="0.214" diaginertia="0.00263797 0.00263797 4.48657e-05"/>
          <joint name="RL_calf_joint" pos="0 0 0" axis="0 1 0" range="-3.14159 3.14159" actuatorfrcrange="-20 20"/>
          <geom size="0.008 0.008 0.1" pos="0 0 -0.1" type="box" rgba="0.462745 0.8 0.992157 1"/>
          <geom size="0.025" pos="0 0 -0.20539" rgba="0.494118 0.494118 0.494118 1"/>
        </body>
      </body>
    </body>
    <body name="FL_hip" pos="0.196 0.049664 0">
      <inertial pos="0 -0.036 0" quat="0.707107 0 0 0.707107" mass="0.57" diaginertia="0.000795577 0.000714827 0.00068875"/>
      <joint name="FL_hip_joint" pos="0 0 0" axis="1 0 0" range="-0.872665 1.0472" actuatorfrcrange="-20 20"/>
      <geom size="0.045 0.04 0.0465" type="box" rgba="0.811765 0.678431 0.301961 1"/>
      <body name="FL_thigh" pos="0 0.077476 0">
        <inertial pos="0 -0.016 -0.11" quat="0.707107 0 0 0.707107" mass="0.634" diaginertia="0.00265482 0.00261821 0.000158764"/>
        <joint name="FL_thigh_joint" pos="0 0 0" axis="0 1 0" range="-0.523599 3.92699" actuatorfrcrange="-20 20"/>
        <geom size="0.0215 0.017 0.11" pos="0 0 -0.11" type="box" rgba="0.462745 0.8 0.992157 1"/>
        <body name="FL_calf" pos="0 0 -0.2115">
          <inertial pos="0 0 -0.161488" mass="0.214" diaginertia="0.00263797 0.00263797 4.48657e-05"/>
          <joint name="FL_calf_joint" pos="0 0 0" axis="0 1 0" range="-3.14159 3.14159" actuatorfrcrange="-20 20"/>
          <geom size="0.008 0.008 0.1" pos="0 0 -0.1" type="box" rgba="0.462745 0.8 0.992157 1"/>
          <geom size="0.025" pos="0 0 -0.20539" rgba="0.494118 0.494118 0.494118 1"/>
        </body>
      </body>
    </body>
    <body name="RR_hip" pos="-0.196 -0.049664 0">
      <inertial pos="0 0.036 0" quat="0.707107 0 0 0.707107" mass="0.57" diaginertia="0.000795577 0.000714827 0.00068875"/>
      <joint name="RR_hip_joint" pos="0 0 0" axis="1 0 0" range="-1.0472 0.872665" actuatorfrcrange="-20 20"/>
      <geom size="0.045 0.04 0.0465" type="box" rgba="0.811765 0.678431 0.301961 1"/>
      <body name="RR_thigh" pos="0 -0.077476 0">
        <inertial pos="0 0.016 -0.11" quat="0.707107 0 0 0.707107" mass="0.634" diaginertia="0.00265482 0.00261821 0.000158764"/>
        <joint name="RR_thigh_joint" pos="0 0 0" axis="0 1 0" range="-0.523599 3.92699" actuatorfrcrange="-20 20"/>
        <geom size="0.0215 0.017 0.11" pos="0 0 -0.11" type="box" rgba="0.462745 0.8 0.992157 1"/>
        <body name="RR_calf" pos="0 0 -0.2115">
          <inertial pos="0 0 -0.161488" mass="0.214" diaginertia="0.00263797 0.00263797 4.48657e-05"/>
          <joint name="RR_calf_joint" pos="0 0 0" axis="0 1 0" range="-3.14159 3.14159" actuatorfrcrange="-20 20"/>
          <geom size="0.008 0.008 0.1" pos="0 0 -0.1" type="box" rgba="0.462745 0.8 0.992157 1"/>
          <geom size="0.025" pos="0 0 -0.20539" rgba="0.494118 0.494118 0.494118 1"/>
        </body>
      </body>
    </body>
    <body name="FR_hip" pos="0.196 -0.049664 0">
      <inertial pos="0 0.036 0" quat="0.707107 0 0 0.707107" mass="0.57" diaginertia="0.000795577 0.000714827 0.00068875"/>
      <joint name="FR_hip_joint" pos="0 0 0" axis="1 0 0" range="-1.0472 0.872665" actuatorfrcrange="-20 20"/>
      <geom size="0.045 0.04 0.0465" type="box" rgba="0.811765 0.678431 0.301961 1"/>
      <body name="FR_thigh" pos="0 -0.077476 0">
        <inertial pos="0 0.016 -0.11" quat="0.707107 0 0 0.707107" mass="0.634" diaginertia="0.00265482 0.00261821 0.000158764"/>
        <joint name="FR_thigh_joint" pos="0 0 0" axis="0 1 0" range="-0.523599 3.92699" actuatorfrcrange="-20 20"/>
        <geom size="0.0215 0.017 0.11" pos="0 0 -0.11" type="box" rgba="0.462745 0.8 0.992157 1"/>
        <body name="FR_calf" pos="0 0 -0.2115">
          <inertial pos="0 0 -0.161488" mass="0.214" diaginertia="0.00263797 0.00263797 4.48657e-05"/>
          <joint name="FR_calf_joint" pos="0 0 0" axis="0 1 0" range="-3.14159 3.14159" actuatorfrcrange="-20 20"/>
          <geom size="0.008 0.008 0.1" pos="0 0 -0.1" type="box" rgba="0.462745 0.8 0.992157 1"/>
          <geom size="0.025" pos="0 0 -0.20539" rgba="0.494118 0.494118 0.494118 1"/>
        </body>
      </body>
    </body>
  </worldbody>
</mujoco>
