<?xml version="1.0" encoding="utf-8"?>
<!--
  MIT Mini Cheetah MuJoCo model
  Converted from URDF: https://github.com/sevocrear/Mini-Cheetah-ROS
  Meshes from: cheetah_description/meshes/
  Kinematics and inertia from the original URDF.
-->
<mujoco model="mini_cheetah">
  <compiler angle="radian" autolimits="true" meshdir="meshes"/>
  <option timestep="0.002" gravity="0 0 -9.81" iterations="50" solver="Newton" cone="elliptic"/>

  <visual>
    <headlight ambient="0.5 0.5 0.5" diffuse="0.8 0.8 0.8" specular="0.1 0.1 0.1"/>
    <map force="0.1" zfar="30"/>
    <quality shadowsize="2048"/>
  </visual>

  <asset>
    <texture type="skybox" builtin="gradient" rgb1="0.4 0.6 0.8" rgb2="0.05 0.05 0.2" width="100" height="100"/>
    <texture name="floor_tex" type="2d" builtin="checker" rgb1="0.6 0.6 0.6" rgb2="0.4 0.4 0.4" width="300" height="300"/>
    <material name="floor_mat" texture="floor_tex" texrepeat="10 10" specular="0.5" shininess="0.3" reflectance="0.1"/>
    <material name="body_mat" rgba="0.82 0.82 0.82 1" specular="0.5" shininess="0.8"/>
    <material name="hip_mat" rgba="0.81 0.68 0.30 1" specular="0.3" shininess="0.5"/>
    <material name="leg_mat" rgba="0.46 0.80 0.99 1" specular="0.3" shininess="0.5"/>
    <material name="foot_mat" rgba="0.49 0.49 0.49 1" specular="0.2" shininess="0.3"/>

    <!-- STL meshes from the Mini-Cheetah-ROS URDF -->
    <mesh name="trunk_mesh" file="trunk.STL"/>
    <mesh name="hip_mesh" file="hip.STL"/>
    <mesh name="thigh_mesh" file="thigh.STL"/>
    <mesh name="calf_mesh" file="calf.STL"/>
    <mesh name="foot_mesh" file="foot.STL"/>
  </asset>

  <default>
    <joint limited="true" armature="0.01" damping="0.5"/>
    <geom condim="6" friction="0.8 0.02 0.01" margin="0.001"/>
    <motor ctrllimited="true" ctrlrange="-20.0 20.0"/>
  </default>

  <worldbody>
    <light name="top" pos="0 0 3" dir="0 0 -1" directional="true" diffuse="0.8 0.8 0.8" specular="0.2 0.2 0.2"/>
    <light name="front" pos="2 -2 2" dir="-1 1 -1" diffuse="0.3 0.3 0.3"/>
    <geom name="floor" type="plane" size="50 50 0.1" material="floor_mat" condim="6" friction="1.0 0.005 0.0001"/>

    <!-- ═══ Base (trunk) ═══ -->
    <body name="base" pos="0 0 0.35">
      <freejoint name="root"/>
      <inertial pos="0 0 0" mass="3.3" diaginertia="0.011253 0.036203 0.042673"/>
      <geom name="trunk_visual" type="mesh" mesh="trunk_mesh" material="body_mat" contype="0" conaffinity="0"/>
      <geom name="trunk_collision" type="box" size="0.15 0.1 0.0465" material="body_mat" contype="0" conaffinity="0"/>
      <site name="imu_site" pos="0 0 0" size="0.01"/>

      <!-- ═══ FR (Front-Right) leg ═══ -->
      <body name="FR_hip" pos="0.196 -0.049664 0">
        <inertial pos="0 0.036 0" quat="0.707107 0 0 0.707107" mass="0.57" diaginertia="0.000795577 0.000714827 0.00068875"/>
        <joint name="FR_hip_joint" axis="1 0 0" range="-1.0472 0.872665" damping="0.5" armature="0.01"/>
        <geom name="FR_hip_visual" type="mesh" mesh="hip_mesh" material="hip_mat" euler="0 3.14159 0" contype="0" conaffinity="0"/>
        <geom name="FR_hip_collision" type="box" size="0.045 0.04 0.0465" contype="0" conaffinity="0"/>
        <body name="FR_thigh" pos="0 -0.077476 0">
          <inertial pos="0 0.016 -0.11" quat="0.707107 0 0 0.707107" mass="0.634" diaginertia="0.00265482 0.00261821 0.000158764"/>
          <joint name="FR_thigh_joint" axis="0 1 0" range="-0.523599 3.92699" damping="0.5" armature="0.01"/>
          <geom name="FR_thigh_visual" type="mesh" mesh="thigh_mesh" material="leg_mat" contype="0" conaffinity="0"/>
          <geom name="FR_thigh_collision" type="box" size="0.0215 0.017 0.11" pos="0 0 -0.11" material="leg_mat" contype="0" conaffinity="0"/>
          <body name="FR_calf" pos="0 0 -0.2115">
            <inertial pos="0 0 -0.161488" mass="0.214" diaginertia="0.00263797 0.00263797 4.48657e-05"/>
            <joint name="FR_calf_joint" axis="0 1 0" range="-3.14159 3.14159" damping="0.5" armature="0.01"/>
            <geom name="FR_calf_visual" type="mesh" mesh="calf_mesh" pos="0 0.009 0" material="leg_mat" contype="0" conaffinity="0"/>
            <geom name="FR_calf_collision" type="box" size="0.008 0.008 0.1" pos="0 0 -0.1" material="leg_mat" contype="0" conaffinity="0"/>
            <body name="FR_foot" pos="0 0 -0.23039">
              <inertial pos="0 0 0" mass="0.15" diaginertia="4.2135e-05 4.2135e-05 4.2135e-05"/>
              <geom name="FR_foot_visual" type="mesh" mesh="foot_mesh" pos="0 0.018 0.02" material="foot_mat" contype="0" conaffinity="0"/>
              <geom name="FR_foot_collision" type="sphere" size="0.025" pos="0 0 0.025" material="foot_mat" condim="6" friction="1.5 0.005 0.0001" solimp="0.9 0.95 0.001" solref="0.02 1"/>
              <site name="FR_foot_site" pos="0 0 0" size="0.01"/>
            </body>
          </body>
        </body>
      </body>

      <!-- ═══ FL (Front-Left) leg ═══ -->
      <body name="FL_hip" pos="0.196 0.049664 0">
        <inertial pos="0 -0.036 0" quat="0.707107 0 0 0.707107" mass="0.57" diaginertia="0.000795577 0.000714827 0.00068875"/>
        <joint name="FL_hip_joint" axis="1 0 0" range="-0.872665 1.0472" damping="0.5" armature="0.01"/>
        <geom name="FL_hip_visual" type="mesh" mesh="hip_mesh" material="hip_mat" euler="3.14159 3.14159 0" contype="0" conaffinity="0"/>
        <geom name="FL_hip_collision" type="box" size="0.045 0.04 0.0465" contype="0" conaffinity="0"/>
        <body name="FL_thigh" pos="0 0.077476 0">
          <inertial pos="0 -0.016 -0.11" quat="0.707107 0 0 0.707107" mass="0.634" diaginertia="0.00265482 0.00261821 0.000158764"/>
          <joint name="FL_thigh_joint" axis="0 1 0" range="-0.523599 3.92699" damping="0.5" armature="0.01"/>
          <geom name="FL_thigh_visual" type="mesh" mesh="thigh_mesh" material="leg_mat" euler="3.14159 3.14159 0" contype="0" conaffinity="0"/>
          <geom name="FL_thigh_collision" type="box" size="0.0215 0.017 0.11" pos="0 0 -0.11" material="leg_mat" contype="0" conaffinity="0"/>
          <body name="FL_calf" pos="0 0 -0.2115">
            <inertial pos="0 0 -0.161488" mass="0.214" diaginertia="0.00263797 0.00263797 4.48657e-05"/>
            <joint name="FL_calf_joint" axis="0 1 0" range="-3.14159 3.14159" damping="0.5" armature="0.01"/>
            <geom name="FL_calf_visual" type="mesh" mesh="calf_mesh" pos="0 0.009 0" material="leg_mat" contype="0" conaffinity="0"/>
            <geom name="FL_calf_collision" type="box" size="0.008 0.008 0.1" pos="0 0 -0.1" material="leg_mat" contype="0" conaffinity="0"/>
            <body name="FL_foot" pos="0 0 -0.23039">
              <inertial pos="0 0 0" mass="0.15" diaginertia="4.2135e-05 4.2135e-05 4.2135e-05"/>
              <geom name="FL_foot_visual" type="mesh" mesh="foot_mesh" pos="0 0.018 0.02" material="foot_mat" contype="0" conaffinity="0"/>
              <geom name="FL_foot_collision" type="sphere" size="0.025" pos="0 0 0.025" material="foot_mat" condim="6" friction="1.5 0.005 0.0001" solimp="0.9 0.95 0.001" solref="0.02 1"/>
              <site name="FL_foot_site" pos="0 0 0" size="0.01"/>
            </body>
          </body>
        </body>
      </body>

      <!-- ═══ RR (Rear-Right) leg ═══ -->
      <body name="RR_hip" pos="-0.196 -0.049664 0">
        <inertial pos="0 0.036 0" quat="0.707107 0 0 0.707107" mass="0.57" diaginertia="0.000795577 0.000714827 0.00068875"/>
        <joint name="RR_hip_joint" axis="1 0 0" range="-1.0472 0.872665" damping="0.5" armature="0.01"/>
        <geom name="RR_hip_visual" type="mesh" mesh="hip_mesh" material="hip_mat" contype="0" conaffinity="0"/>
        <geom name="RR_hip_collision" type="box" size="0.045 0.04 0.0465" contype="0" conaffinity="0"/>
        <body name="RR_thigh" pos="0 -0.077476 0">
          <inertial pos="0 0.016 -0.11" quat="0.707107 0 0 0.707107" mass="0.634" diaginertia="0.00265482 0.00261821 0.000158764"/>
          <joint name="RR_thigh_joint" axis="0 1 0" range="-0.523599 3.92699" damping="0.5" armature="0.01"/>
          <geom name="RR_thigh_visual" type="mesh" mesh="thigh_mesh" material="leg_mat" contype="0" conaffinity="0"/>
          <geom name="RR_thigh_collision" type="box" size="0.0215 0.017 0.11" pos="0 0 -0.11" material="leg_mat" contype="0" conaffinity="0"/>
          <body name="RR_calf" pos="0 0 -0.2115">
            <inertial pos="0 0 -0.161488" mass="0.214" diaginertia="0.00263797 0.00263797 4.48657e-05"/>
            <joint name="RR_calf_joint" axis="0 1 0" range="-3.14159 3.14159" damping="0.5" armature="0.01"/>
            <geom name="RR_calf_visual" type="mesh" mesh="calf_mesh" pos="0 0.009 0" material="leg_mat" contype="0" conaffinity="0"/>
            <geom name="RR_calf_collision" type="box" size="0.008 0.008 0.1" pos="0 0 -0.1" material="leg_mat" contype="0" conaffinity="0"/>
            <body name="RR_foot" pos="0 0 -0.23039">
              <inertial pos="0 0 0" mass="0.15" diaginertia="4.2135e-05 4.2135e-05 4.2135e-05"/>
              <geom name="RR_foot_visual" type="mesh" mesh="foot_mesh" pos="0 0.018 0.02" material="foot_mat" contype="0" conaffinity="0"/>
              <geom name="RR_foot_collision" type="sphere" size="0.025" pos="0 0 0.025" material="foot_mat" condim="6" friction="1.5 0.005 0.0001" solimp="0.9 0.95 0.001" solref="0.02 1"/>
              <site name="RR_foot_site" pos="0 0 0" size="0.01"/>
            </body>
          </body>
        </body>
      </body>

      <!-- ═══ RL (Rear-Left) leg ═══ -->
      <body name="RL_hip" pos="-0.196 0.049664 0">
        <inertial pos="0 -0.036 0" quat="0.707107 0 0 0.707107" mass="0.57" diaginertia="0.000795577 0.000714827 0.00068875"/>
        <joint name="RL_hip_joint" axis="1 0 0" range="-0.872665 1.0472" damping="0.5" armature="0.01"/>
        <geom name="RL_hip_visual" type="mesh" mesh="hip_mesh" material="hip_mat" euler="3.14159 0 0" contype="0" conaffinity="0"/>
        <geom name="RL_hip_collision" type="box" size="0.045 0.04 0.0465" contype="0" conaffinity="0"/>
        <body name="RL_thigh" pos="0 0.077476 0">
          <inertial pos="0 -0.016 -0.11" quat="0.707107 0 0 0.707107" mass="0.634" diaginertia="0.00265482 0.00261821 0.000158764"/>
          <joint name="RL_thigh_joint" axis="0 1 0" range="-0.523599 3.92699" damping="0.5" armature="0.01"/>
          <geom name="RL_thigh_visual" type="mesh" mesh="thigh_mesh" material="leg_mat" euler="3.14159 3.14159 0" contype="0" conaffinity="0"/>
          <geom name="RL_thigh_collision" type="box" size="0.0215 0.017 0.11" pos="0 0 -0.11" material="leg_mat" contype="0" conaffinity="0"/>
          <body name="RL_calf" pos="0 0 -0.2115">
            <inertial pos="0 0 -0.161488" mass="0.214" diaginertia="0.00263797 0.00263797 4.48657e-05"/>
            <joint name="RL_calf_joint" axis="0 1 0" range="-3.14159 3.14159" damping="0.5" armature="0.01"/>
            <geom name="RL_calf_visual" type="mesh" mesh="calf_mesh" pos="0 0.009 0" material="leg_mat" contype="0" conaffinity="0"/>
            <geom name="RL_calf_collision" type="box" size="0.008 0.008 0.1" pos="0 0 -0.1" material="leg_mat" contype="0" conaffinity="0"/>
            <body name="RL_foot" pos="0 0 -0.23039">
              <inertial pos="0 0 0" mass="0.15" diaginertia="4.2135e-05 4.2135e-05 4.2135e-05"/>
              <geom name="RL_foot_visual" type="mesh" mesh="foot_mesh" pos="0 0.018 0.02" material="foot_mat" contype="0" conaffinity="0"/>
              <geom name="RL_foot_collision" type="sphere" size="0.025" pos="0 0 0.025" material="foot_mat" condim="6" friction="1.5 0.005 0.0001" solimp="0.9 0.95 0.001" solref="0.02 1"/>
              <site name="RL_foot_site" pos="0 0 0" size="0.01"/>
            </body>
          </body>
        </body>
      </body>

    </body>
  </worldbody>

  <!-- Actuators: one motor per joint, order FR/FL/RR/RL × hip/thigh/calf -->
  <actuator>
    <motor name="FR_hip_motor"   joint="FR_hip_joint"   gear="1"/>
    <motor name="FR_thigh_motor" joint="FR_thigh_joint" gear="1"/>
    <motor name="FR_calf_motor"  joint="FR_calf_joint"  gear="1"/>
    <motor name="FL_hip_motor"   joint="FL_hip_joint"   gear="1"/>
    <motor name="FL_thigh_motor" joint="FL_thigh_joint" gear="1"/>
    <motor name="FL_calf_motor"  joint="FL_calf_joint"  gear="1"/>
    <motor name="RR_hip_motor"   joint="RR_hip_joint"   gear="1"/>
    <motor name="RR_thigh_motor" joint="RR_thigh_joint" gear="1"/>
    <motor name="RR_calf_motor"  joint="RR_calf_joint"  gear="1"/>
    <motor name="RL_hip_motor"   joint="RL_hip_joint"   gear="1"/>
    <motor name="RL_thigh_motor" joint="RL_thigh_joint" gear="1"/>
    <motor name="RL_calf_motor"  joint="RL_calf_joint"  gear="1"/>
  </actuator>

  <sensor>
    <framelinvel name="base_linvel" objtype="site" objname="imu_site"/>
    <frameangvel name="base_angvel" objtype="site" objname="imu_site"/>
    <framequat name="base_quat" objtype="site" objname="imu_site"/>
    <accelerometer name="base_accel" site="imu_site"/>
    <gyro name="base_gyro" site="imu_site"/>
  </sensor>
</mujoco>
